<?xml version="1.0" ?>
<!-- =================================================================================== -->
<!-- |    This document was autogenerated by xacro from box_bot.xacro                  | -->
<!-- |    EDITING THIS FILE BY HAND IS NOT RECOMMENDED                                 | -->
<!-- =================================================================================== -->
<robot name="yolobot">
  <material name="black">
    <color rgba="0.0 0.0 0.0 1.0"/>
  </material>
  <material name="blue">
    <color rgba="0.203125 0.23828125 0.28515625 1.0"/>
  </material>
  <material name="green">
    <color rgba="0.0 0.8 0.0 1.0"/>
  </material>
  <material name="grey">
    <color rgba="0.2 0.2 0.2 1.0"/>
  </material>
  <material name="orange">
    <color rgba="1.0 0.423529411765 0.0392156862745 1.0"/>
  </material>
  <material name="brown">
    <color rgba="0.870588235294 0.811764705882 0.764705882353 1.0"/>
  </material>
  <material name="red">
    <color rgba="0.80078125 0.12890625 0.1328125 1.0"/>
  </material>
  <material name="white">
    <color rgba="1.0 1.0 1.0 1.0"/>
  </material>
  <gazebo reference="chassis">
    <material>Gazebo/Blue</material>
  </gazebo>
    <gazebo reference="front_left_wheel">
    <kp>1000.0</kp>
    <kd>1000.0</kd>
    <mu1>0.5</mu1>
    <mu2>0.5</mu2>
    <material>Gazebo/Black</material>
  </gazebo>
  <gazebo reference="front_right_wheel">
    <kp>1000.0</kp>
    <kd>1000.0</kd>
    <mu1>0.5</mu1>
    <mu2>0.5</mu2>
    <material>Gazebo/Black</material>
  </gazebo>
  <gazebo reference="back_left_wheel">
    <kp>1000.0</kp>
    <kd>1000.0</kd>
    <mu1>0.5</mu1>
    <mu2>0.5</mu2>
    <material>Gazebo/Black</material>
  </gazebo>
  <gazebo reference="back_right_wheel">
    <kp>1000.0</kp>
    <kd>1000.0</kd>
    <mu1>0.5</mu1>
    <mu2>0.5</mu2>
    <material>Gazebo/Black</material>
  </gazebo>
    <gazebo reference="column_link">
    <kp>1000.0</kp>
    <kd>1000.0</kd>
    <mu1>0.5</mu1>
    <mu2>0.5</mu2>
    <material>Gazebo/Grey</material>
  </gazebo>
  <!-- ros_control plugin -->
  <gazebo>
    <plugin filename="libgazebo_ros_control.so" name="gazebo_ros_control">
      <robotNamespace>/yolobot</robotNamespace>
      <robotParam>/robot_description</robotParam>
      <robotSimType>gazebo_ros_control/DefaultRobotHWSim</robotSimType>
    </plugin>
    </gazebo>
    
	<gazebo>
		<plugin name="my_robo" filename="libgazebo_ros_planar_move.so">
      		<commandTopic>cmd_vel</commandTopic>
      		<odometryTopic>odom</odometryTopic>
      		<odometryFrame>odom</odometryFrame>
      		<odometryRate>20.0</odometryRate>
      		<robotBaseFrame>base_foorprint</robotBaseFrame>
			<publishTF>true</publishTF>
    	</plugin>
  </gazebo>

  <link name="robot_footprint">
  	</link>

 <link name="chassis">
    <!-- pose and inertial -->
    <pose>0 0 0.1 0 0 0</pose>
    <inertial>
      <mass value="15.0"/>
      <origin xyz="0.0 0 0" rpy=" 0 0 0"/>
      <inertia ixx="0.1" ixy="0" ixz="0" iyy="0.1" iyz="0" izz="0.1" />
    </inertial>
    
    <!-- body -->
    <collision name='collision'>
      <origin xyz="0 0 0" rpy=" 0 0 0"/>
      <geometry>
        <box size=".4 .2 .1"/>
      </geometry>
    </collision>
    
    <visual name='chassis_visual'>
      <origin xyz="0 0 0" rpy=" 0 0 0"/>
      <geometry>
        <box size=".4 .2 .1"/>
      </geometry>
    </visual>
  </link>
  
   <joint name="robot_footprint_joint" type="fixed">
    <origin xyz="0 0 0" rpy="0 0 0" />
    <parent link="robot_footprint"/>
    <child link="chassis" />
  </joint>
  


  <!-- CAMERA-->
  <link name='rgb_cam_camera_link'>
		<visual>
			<origin xyz="0 0 0" rpy="0 0 0"/>

			<geometry>
				
				<box size="0.08 0.08 0.04"/>
			</geometry>
		</visual>
	</link>

  <joint name="rgb_cam_camera_link_joint" type="fixed">
		<origin rpy="0 0 0" xyz="0.04 0.0 0.5"/>
		<parent link="chassis"/>
		<child link="rgb_cam_camera_link"/>
	</joint>


    <link name="rgb_cam_camera_link_frame">
    </link>

    <joint name="rgb_cam_camera_frame_joint" type="fixed">
        <origin xyz="0.01 0 0" rpy="0 0 0" />
        <parent link="rgb_cam_camera_link" />
        <child link="rgb_cam_camera_link_frame" />
        <axis xyz="0 0 0"/>
    </joint>


    <gazebo reference="rgb_cam_camera_link_frame">
      <sensor type="camera" name="rgb_cam">
        <always_on>1</always_on>
        <update_rate>10.0</update_rate>
        <camera name="rgb_cam">
            <pose>0 0 0 0 0 0</pose>
            <horizontal_fov>1.3962634</horizontal_fov>
            <image>
             <width>640</width>
             <height>480</height>
             <format>R8G8B8</format>
            </image>
            <clip>
                <near>0.005</near>
                <far>20.0</far>
            </clip>
        </camera>
        <plugin name="camera_controller" filename="libgazebo_ros_camera.so">
            <alwaysOn>true</alwaysOn>
            <updateRate>0.0</updateRate>
            <cameraName>rgb_cam</cameraName>
            <imageTopicName>image_raw</imageTopicName>
            <cameraInfoTopicName>camera_info</cameraInfoTopicName>
            <frameName>rgb_cam_camera_link_frame</frameName>
            <hackBaseline>0.07</hackBaseline>
            <distortionK1>0.0</distortionK1>
            <distortionK2>0.0</distortionK2>
            <distortionK3>0.0</distortionK3>
            <distortionT1>0.0</distortionT1>
            <distortionT2>0.0</distortionT2>
        </plugin>
      </sensor>
    </gazebo>

  <link name="front_left_wheel">
    <inertial>
      <mass value="5.0"/>
      <origin xyz="0.0 0 0" rpy=" 0 1.5707 1.5707"/>
      <inertia ixx="0.1" ixy="0" ixz="0" iyy="0.1" iyz="0" izz="0.1" />
    </inertial>

    <visual>
      <origin xyz="0.0 0 0" rpy=" 0 1.5707 1.5707"/>
      <geometry>
        <cylinder length="0.05" radius="0.05"/>
      </geometry>
    </visual>

    <collision>
      <origin xyz="0.0 0 0" rpy=" 0 1.5707 1.5707"/>
      <geometry>
        <cylinder length="0.05" radius="0.05"/>
      </geometry>
    </collision>
  </link>

  <link name="back_left_wheel">
    <inertial>
      <mass value="5.0"/>
      <origin xyz="0.0 0 0" rpy=" 0 1.5707 1.5707"/>
      <inertia ixx="0.1" ixy="0" ixz="0" iyy="0.1" iyz="0" izz="0.1" />
    </inertial>

    <visual>
      <origin xyz="0.0 0 0" rpy=" 0 1.5707 1.5707"/>
      <geometry>
        <cylinder length="0.05" radius="0.05"/>
      </geometry>
    </visual>

    <collision>
      <origin xyz="0.0 0 0" rpy=" 0 1.5707 1.5707"/>
      <geometry>
        <cylinder length="0.05" radius="0.05"/>
      </geometry>
    </collision>
  </link>

  <link name="front_right_wheel">
    <inertial>
      <mass value="5.0"/>
      <origin xyz="0.0 0 0" rpy=" 0 1.5707 1.5707"/>
      <inertia ixx="0.1" ixy="0" ixz="0" iyy="0.1" iyz="0" izz="0.1" />
    </inertial>

    <visual>
      <origin xyz="0.0 0 0" rpy=" 0 1.5707 1.5707"/>
      <geometry>
        <cylinder length="0.05" radius="0.05"/>
      </geometry>
    </visual>

    <collision>
      <origin xyz="0.0 0 0" rpy=" 0 1.5707 1.5707"/>
      <geometry>
        <cylinder length="0.05" radius="0.05"/>
      </geometry>
    </collision>
  </link>

  <link name="back_right_wheel">
    <inertial>
      <mass value="5.0"/>
      <origin xyz="0.0 0 0" rpy=" 0 1.5707 1.5707"/>
      <inertia ixx="0.1" ixy="0" ixz="0" iyy="0.1" iyz="0" izz="0.1" />
    </inertial>

    <visual>
      <origin xyz="0.0 0 0" rpy=" 0 1.5707 1.5707"/>
      <geometry>
        <cylinder length="0.05" radius="0.05"/>
      </geometry>
    </visual>

    <collision>
      <origin xyz="0.0 0 0" rpy=" 0 1.5707 1.5707"/>
      <geometry>
        <cylinder length="0.05" radius="0.05"/>
      </geometry>
    </collision>
  </link>
      <link name="column_link">
       <mass  value="5.0" />
          <origin xyz="0 0 0" rpy="0 0 0"/>
       <inertia ixx="0.1" ixy="0" ixz="0" iyy="0.1" iyz="0" izz="0.1" />
        <visual>
        <origin xyz="0 0 0" rpy="0 0 0"/>
            <geometry>
                <cylinder radius="0.03" length="0.45"/>
            </geometry>
            <material name="blue"/>
        </visual>
        <collision>
        <origin xyz="0 0 0" rpy="0 0 0"/>
            <geometry>
                <cylinder radius="0.03" length="0.45"/>
            </geometry>
        </collision>
       
    </link>
    
        <joint type="fixed" name="column_link_joint">
    <origin xyz="0.04 0 0.265" rpy="0 0 0"/>
    <child link="column_link"/>
    <parent link="chassis"/>
    <axis xyz="0 1 0" rpy="0 0 0"/>
    <limit effort="10000" velocity="1000"/>
    <dynamics damping="1.0" friction="1.0"/>
  </joint>
    
    <joint type="continuous" name="front_left_wheel_joint">
    <origin xyz="0.12 0.15 0" rpy="0 0 0"/>
    <child link="front_left_wheel"/>
    <parent link="chassis"/>
    <axis xyz="0 1 0" rpy="0 0 0"/>
    <limit effort="10000" velocity="1000"/>
    <dynamics damping="1.0" friction="1.0"/>
  </joint>

  <joint type="continuous" name="front_right_wheel_joint">
    <origin xyz="0.12 -0.15 0" rpy="0 0 0"/>
    <child link="front_right_wheel"/>
    <parent link="chassis"/>
    <axis xyz="0 1 0" rpy="0 0 0"/>
    <limit effort="10000" velocity="1000"/>
    <dynamics damping="1.0" friction="1.0"/>
  </joint>

  <joint type="continuous" name="back_left_wheel_joint">
    <origin xyz="-0.12 0.15 0" rpy="0 0 0"/>
    <child link="back_left_wheel"/>
    <parent link="chassis"/>
    <axis xyz="0 1 0" rpy="0 0 0"/>
    <limit effort="10000" velocity="1000"/>
    <dynamics damping="1.0" friction="1.0"/>
  </joint>

  <joint type="continuous" name="back_right_wheel_joint">
    <origin xyz="-0.12 -0.15 0" rpy="0 0 0"/>
    <child link="back_right_wheel"/>
    <parent link="chassis"/>
    <axis xyz="0 1 0" rpy="0 0 0"/>
    <limit effort="10000" velocity="1000"/>
    <dynamics damping="1.0" friction="1.0"/>
  </joint>

</robot>

